<?xml version="1.0"?>
<robot name="base" xmlns:xacro="http://ros.org/wiki/xacro">

  <xacro:include filename="$(find base_robot)/models/base.gazebo" />
	
	<xacro:arg name="robot_param" default="robot_description"/>
	<xacro:base_gazebo robot_parameter_name="$(arg robot_param)"/>

	<xacro:property name="pi" value="3.1415" />

  <xacro:macro name="cylinder_inertia" params="m r h">
    <inertia  ixx="${m*(3*r*r+h*h)/12}" ixy = "0" ixz = "0"
      iyy="${m*(3*r*r+h*h)/12}" iyz = "0"
      izz="${m*r*r/2}"
    />
  </xacro:macro>

  <xacro:macro name="box_inertia" params="m x y z">
    <inertia  ixx="${m*(y*y+z*z)/12}" ixy = "0" ixz = "0"
      iyy="${m*(x*x+z*z)/12}" iyz = "0"
      izz="${m*(x*x+z*z)/12}"
    />
  </xacro:macro>

  <xacro:macro name="sphere_inertia" params="m r">
    <inertia  ixx="${2*m*r*r/5}" ixy = "0" ixz = "0"
      iyy="${2*m*r*r/5}" iyz = "0"
      izz="${2*m*r*r/5}"
    />
  </xacro:macro>

  <material name="red">
    <color rgba="0.8 0 0 1"/>
  </material>
		
  <material name="green">
    <color rgba="0 0.8 0 1"/>
  </material>

  <material name="blue">
    <color rgba="0 0 0.8 1"/>
  </material>

  <material name="white">
    <color rgba="1 1 1 1"/>
  </material>

	<material name="black">
    <color rgba="0 0 0 1"/>
  </material>

	<link name="base_link">
		<visual>
			<geometry>
				<cylinder length="0.10" radius="0.20"/>
			</geometry>
			<material name="blue"/>
		</visual>
    <collision>
      <geometry>
        <cylinder length="0.10" radius="0.20"/>
      </geometry>
    </collision>
		<inertial>
      <mass value="1"/>
      <!--inertia ixx="0.541" ixy="0.0" ixz="0.0" iyy="0.541" iyz="0.0" izz="1"/-->
			<xacro:cylinder_inertia m="1" r="0.20" h="0.10"/>
    </inertial>
	</link>
		
	<xacro:macro name="wheel" params="prefix reflect">
		<link name="${prefix}_wheel">
			<visual>
				<geometry>
					<cylinder length="0.03" radius="0.10"/>
				</geometry>
				<origin rpy="${pi/2} 0 0" xyz="0 0 0"/>
				<material name="white"/>
			</visual>
			<collision>
		    <geometry>
		      <cylinder length="0.03" radius="0.10"/>
		    </geometry>
		    <origin rpy="${pi/2} 0 0" xyz="0 0 0"/>
		  </collision>
		  <inertial>
		    <mass value="0.1"/>
		    <!--inertia ixx="0.001" ixy="0.0" ixz="0.0" iyy="0.001" iyz="0.0" izz="0.001"/-->
				<xacro:cylinder_inertia m="0.1" r="0.10" h="0.03"/>
		  </inertial>
		</link>
		<joint name="${prefix}_wheel_joint" type="continuous">
			<parent link="base_link"/>
			<child link="${prefix}_wheel"/>
			<axis xyz="0 1 0"/>
			<origin xyz="0 ${-1*reflect*0.215} 0"/>
		</joint>

    <transmission name="${prefix}_wheel_trans">
      <type>transmission_interface/SimpleTransmission</type>
      <actuator name="${prefix}_wheel_motor">
        <mechanicalReduction>1</mechanicalReduction>
      </actuator>
      <joint name="${prefix}_wheel_joint">
        <hardwareInterface>hardware_interface/VelocityJointInterface</hardwareInterface>
      </joint>
    </transmission>

	</xacro:macro>
	
	<xacro:wheel prefix="right" reflect="1"/>
	<xacro:wheel prefix="left" reflect="-1"/>
	
	<xacro:macro name="caster" params="prefix reflect">
		<link name="${prefix}_caster">
			<visual>
				<geometry>
					<sphere radius="0.05"/>
				</geometry>
				<origin rpy="0 0 0" xyz="0 0 0"/>
				<material name="black"/>
			</visual>
			<collision>
		    <geometry>
		      <sphere radius="0.05"/>
		    </geometry>
		    <origin rpy="0 0 0" xyz="0 0 0"/>
		  </collision>
		  <inertial>
		    <mass value="0.01"/>
		    <xacro:sphere_inertia m="0.01" r="0.05"/>
		  </inertial>
		</link>
		<joint name="${prefix}_caster_joint" type="fixed">
			<parent link="base_link"/>
			<child link="${prefix}_caster"/>
			<origin xyz="${reflect*0.15} 0 -0.05"/>
		</joint>
	</xacro:macro>
  
	<xacro:caster prefix="front" reflect="1"/>
	<xacro:caster prefix="rear" reflect="-1"/>
  
  <!-- Hokuyo Laser -->
  <link name="hokuyo_link">
    <collision>
      <origin xyz="0 0 0" rpy="0 0 0"/>
      <geometry>
    <box size="0.1 0.1 0.1"/>
      </geometry>
    </collision>

    <visual>
      <origin xyz="0 0 0" rpy="0 0 0"/>
      <geometry>
        <mesh filename="package://base_robot/meshes/hokuyo.dae"/>
      </geometry>
    </visual>

    <inertial>
      <mass value="1e-5" />
      <origin xyz="0 0 0" rpy="0 0 0"/>
      <inertia ixx="1e-6" ixy="0" ixz="0" iyy="1e-6" iyz="0" izz="1e-6" />
    </inertial>
  </link>


  <joint name="hokuyo_joint" type="fixed">
    <axis xyz="0 1 0" />
    <origin xyz="0.15 0 0.08" rpy="0 0 0"/>
    <parent link="base_link"/>
    <child link="hokuyo_link"/>
  </joint>

	<link name="camera">
    <collision>
      <origin xyz="0 0 0" rpy="0 0 0"/>
      <geometry>
        <box size="0.05 0.05 0.05"/>
      </geometry>
    </collision>

    <visual>
      <origin xyz="0 0 0" rpy="0 0 0"/>
      <geometry>
        <box size="0.05 0.05 0.05"/>
      </geometry>
      <material name="green"/>
    </visual>

    <inertial>
      <mass value="0.1" />
      <origin xyz="0 0 0" rpy="0 0 0"/>
      <box_inertia m="0.1" x="0.05" y="0.05" z="0.05" />
      <inertia ixx="1e-6" ixy="0" ixz="0" iyy="1e-6" iyz="0" izz="1e-6" />
    </inertial>
  </link>

  <joint name="camera_joint" type="fixed">
    <axis xyz="0 1 0" />
    <origin xyz="0.2 0 0" rpy="0 0 0"/>
    <parent link="base_link"/>
    <child link="camera"/>
  </joint>


</robot>
